<?xml version="1.0" encoding="UTF-8"?>
<!-- Generated by org.testng.reporters.JUnitReportReporter -->
<testsuite hostname="LIN-PF312D66" failures="1" tests="3" name="Automation.Arijit_Framework.ErrorValidation" time="67.051" errors="0" timestamp="2024-04-23T21:52:47 IST" skipped="1">
  <testcase classname="Automation.Arijit_Framework.ErrorValidation" name="erroValidate" time="14.386"/>
  <system-out/>
  <testcase classname="Automation.Arijit_Framework.ErrorValidation" name="erroValidate2" time="15.110">
    <failure message="expected [Invalid email address or password entered] but found [Invalid email address o password entered]" type="java.lang.AssertionError">
      <![CDATA[java.lang.AssertionError: expected [Invalid email address or password entered] but found [Invalid email address o password entered]
at org.testng.Assert.fail(Assert.java:110)
at org.testng.Assert.failNotEquals(Assert.java:1577)
at org.testng.Assert.assertEqualsImpl(Assert.java:149)
at org.testng.Assert.assertEquals(Assert.java:131)
at org.testng.Assert.assertEquals(Assert.java:655)
at org.testng.Assert.assertEquals(Assert.java:665)
at Automation.Arijit_Framework.ErrorValidation.erroValidate2(ErrorValidation.java:22)
at java.base/jdk.internal.reflect.NativeMethodAccessorImpl.invoke0(Native Method)
at java.base/jdk.internal.reflect.NativeMethodAccessorImpl.invoke(NativeMethodAccessorImpl.java:77)
at java.base/jdk.internal.reflect.DelegatingMethodAccessorImpl.invoke(DelegatingMethodAccessorImpl.java:43)
at java.base/java.lang.reflect.Method.invoke(Method.java:568)
at org.testng.internal.invokers.MethodInvocationHelper.invokeMethod(MethodInvocationHelper.java:139)
at org.testng.internal.invokers.TestInvoker.invokeMethod(TestInvoker.java:677)
at org.testng.internal.invokers.TestInvoker.retryFailed(TestInvoker.java:263)
at org.testng.internal.invokers.MethodRunner.runInSequence(MethodRunner.java:62)
at org.testng.internal.invokers.TestInvoker$MethodInvocationAgent.invoke(TestInvoker.java:969)
at org.testng.internal.invokers.TestInvoker.invokeTestMethods(TestInvoker.java:194)
at org.testng.internal.invokers.TestMethodWorker.invokeTestMethods(TestMethodWorker.java:148)
at org.testng.internal.invokers.TestMethodWorker.run(TestMethodWorker.java:128)
at java.base/java.util.ArrayList.forEach(ArrayList.java:1511)
at org.testng.TestRunner.privateRun(TestRunner.java:829)
at org.testng.TestRunner.run(TestRunner.java:602)
at org.testng.SuiteRunner.runTest(SuiteRunner.java:437)
at org.testng.SuiteRunner$SuiteWorker.run(SuiteRunner.java:475)
at org.testng.internal.thread.ThreadUtil.lambda$execute$0(ThreadUtil.java:58)
at java.base/java.util.concurrent.FutureTask.run(FutureTask.java:264)
at java.base/java.util.concurrent.ThreadPoolExecutor.runWorker(ThreadPoolExecutor.java:1136)
at java.base/java.util.concurrent.ThreadPoolExecutor$Worker.run(ThreadPoolExecutor.java:635)
at java.base/java.lang.Thread.run(Thread.java:840)
]]>
    </failure>
  </testcase> <!-- erroValidate2 -->
  <system-out/>
  <testcase classname="Automation.Arijit_Framework.ErrorValidation" name="erroValidate2" time="37.555">
    <skipped/>
  </testcase> <!-- erroValidate2 -->
  <system-out/>
</testsuite> <!-- Automation.Arijit_Framework.ErrorValidation -->
